Workbook

Sheet Summary
A2: Summary of results
A3: 1.0. | B3: Per Capita per day generation (kg/person/day) | C3: 0.64588423 | G3: Solid waste composition | K3: Average
A4: 2.0. | B4: Average volume of solid waste (litres) | C4: 63.520299 | G4: Food Waste | H4: 0.7850834 | I4: 0.81921315 | J4: 0.75369348 | K4: =AVERAGE(H4:J4) -> 0.78599667
A5: 3.0. | B5: Average density (kg/L) | C5: 0.42146628 | G5: Garden and Yard wastes | H5: 0.076318112 | I5: 0.023813387 | J5: 0.089624782 | K5: 0.063252093
A6: 4.0. | B6: Solid waste composition | G6: Wood | H6: 0.00090033867 | I6: 0.00076930178 | J6: 0.00066770183 | K6: 0.00077911409
B7: Food Waste | C7: 0.78599667 | G7: Textiles | H7: 0.014308031 | I7: 0.017589969 | J7: 0.0033326667 | K7: 0.011743556
B8: Garden and Yard wastes | C8: 0.063252093 | G8: Paper and pulp | H8: 0.0046547311 | I8: 0.025981419 | J8: 0.017479599 | K8: 0.016038583
B9: Wood | C9: 0.00077911409 | G9: Polythene Bags | H9: 0.053833495 | I9: 0.031333895 | J9: 0.027388795 | K9: 0.037518728
B10: Textiles | C10: 0.011743556 | G10: Plastics and Rubber | H10: 0.029391188 | I10: 0.01805528 | J10: 0.036695223 | K10: 0.02804723
B11: Paper and pulp | C11: 0.016038583 | G11: Glass | H11: 5.7637575e-05 | I11: 0.0025666705 | J11: 0.00060927792 | K11: 0.001077862
B12: Polythene Bags | C12: 0.037518728 | G12: Metals | H12: 0.00093015121 | I12: 0.0020211656 | J12: 0.0068506207 | K12: 0.0032673125
B13: Plastics and Rubber | C13: 0.02804723 | G13: Others | H13: 0.03452292 | I13: 0.058655764 | J13: 0.063657858 | K13: 0.052278847
B14: Glass | C14: 0.001077862 | G14: Total | H14: =SUM(H4:H13) -> 1 | I14: =SUM(I4:I13) -> 1 | J14: =SUM(J4:J13) -> 1 | K14: 1
B15: Metals | C15: 0.0032673125
B16: Others | C16: 0.052278847 | G16: NB: Others included mostly Ash and Pampers
A17: Total | C17: 1
B21: Bwaise I (low-income) | C21: Bukoto I (middle income) | D21: Ggaba (high income) | G21: Density
G22: Area | H22: Bwaise I | I22: Bukoto I | J22: Ggaba
A23: Households Pariticipation | G23: Average volume (litres) | H23: 39.435897 | I23: 31.4375 | J23: 119.6875
A24: Total Number of Households | B24: 55 | C24: 44 | D24: 40 | G24: Average density (kg/L) | H24: 0.36811796 | I24: 0.57128683 | J24: 0.32499407
A25: Number of Households that complied | B25: 39 | C25: 32 | D25: 32
A26: Response rate | B26: =B25/B24 -> 0.70909091 | C26: =C25/C24 -> 0.72727273 | D26: =D25/D24 -> 0.8
A27: Solid waste Quantification
A28: Per Capita per day generation (kg/person/day) | B28: 0.42662958 | C28: 0.53161747 | D28: 0.97940563

Sheet Bwaise I
A1: Solid waste Characterisation in Selected Households in Bwaise I
B2: For Bwaise 1, the number of households that were required were 48. Bin bags were supplied to 55 households between 14th and 25th January, though only 39 households complied and the data collected using the survey questionaires for the 39 households is shown in the table below.
A3: No. | B3: Household ID | C3: Division | D3: Parish | E3: Zone | F3: Socio-economic factors (from proposal) | K3: Other household charactristics investigated | O3: Housing facilities | W3: Amount of olid waste collected over 7days (kg) | AG3: Total waste generated(kg) | AH3: Generation per day (kg/day) | AI3: Per Capita Generation(kg/day) | AJ3: Volume(L) | AK3: Density(kg/L)
F4: Income level | G4: Number of occupants | H4: Age of household head | I4: Gender of Household head | J4: Education level of Household head | K4: Profession of Household head | L4: Monthly income | M4: Respondent | N4: Period of Stay in the area | O4: Type of occupancy | P4: Quality of Housing | Q4: Roof material | R4: Wall material | S4: Floor Material | T4: Access to clean Water | U4: Sanitation Facilities | V4: Condition of access road | W4: Food Waste | X4: Garden and Yard wastes | Y4: Wood | Z4: Textiles | AA4: Paper and pulp | AB4: Polythene Bags | AC4: Plastics and Rubber | AD4: Glass | AE4: Metals | AF4: Others
A5: 1 | B5: Household_1 | C5: Kawenpe Division | D5: Bwaise I | E5: Lubagge | F5: low-income | G5: 3 | H5: 18-35 years | I5: Male | J5: Secondary | K5: Business | L5: <500,000 | M5: Spouse | N5: 1-3 years | O5: Rented | P5: Bungalow | Q5: Iron Sheets/titles | R5: Bricks | S5: Cemented | T5: Yard Tap | U5: Shared Facilities | V5: unpaved | W5: =7.32-0.33 -> 6.99 | X5: =(219-125)/1000 -> 0.094 | Y5: 0 | Z5: =(152-125)/1000 -> 0.027 | AA5: =(142-125)/1000 -> 0.017 | AB5: =(202-125)/1000 -> 0.077 | AC5: =(202-125)/1000 -> 0.077 | AD5: 0 | AE5: 0 | AF5: =(167-125)/1000 -> 0.042 | AG5: =SUM(W5:AF5) -> 7.324 | AH5: =(AG5/7) -> 1.0462857 | AI5: =AH5/G5 -> 0.3487619 | AJ5: 10 | AK5: =4.74/10 -> 0.474
A6: 2 | B6: Household_2 | C6: Kawenpe Division | D6: Bwaise I | E6: Lubagge | F6: low-income | G6: 7 | H6: 36-60 years | I6: Male | J6: Illiterate | K6: Business | L6: 500,000 - 1,000,000 | M6: Son/Daughter | N6: > 5 years | O6: Occupied by owner | P6: Bungalow | Q6: Iron Sheets/titles | R6: Bricks | S6: Tiles | T6: Yard Tap | U6: Not Shared Facilities | V6: unpaved | W6: =13.42-0.33*3 -> 12.43 | X6: 0 | Y6: 0 | Z6: =(166-125)/1000 -> 0.041 | AA6: =(425-125)/1000 -> 0.3 | AB6: =(547-330)/1000 -> 0.217 | AC6: =(263-125)/1000 -> 0.138 | AD6: 0 | AE6: 0 | AF6: 0 | AG6: =SUM(W6:AF6) -> 13.126 | AH6: =(AG6/7) -> 1.8751429 | AI6: =AH6/G6 -> 0.26787755 | AJ6: 30 | AK6: =AG6/AJ6 -> 0.43753333
A7: 3 | B7: Household_3 | C7: Kawenpe Division | D7: Bwaise I | E7: Lubagge | F7: low-income | G7: 6 | H7: 36-60 years | I7: Female | J7: Secondary | K7: Business | L7: 500,000 - 1,000,000 | M7: Household head | N7: > 5 years | O7: Occupied by owner | P7: Bungalow | Q7: Iron Sheets/titles | R7: Bricks | S7: Tiles | T7: Yard Tap | U7: Shared Facilities | V7: unpaved | W7: 0 | X7: 0 | Y7: 0 | Z7: 0 | AA7: 0 | AB7: 4.56 | AC7: 0 | AD7: 0 | AE7: 0 | AF7: 0 | AG7: =SUM(W7:AF7) -> 4.56 | AH7: =(AG7/7) -> 0.65142857 | AI7: =AH7/G7 -> 0.10857143 | AJ7: 12 | AK7: =AG7/AJ7 -> 0.38
A8: 4 | B8: Household_5 | C8: Kawenpe Division | D8: Bwaise I | E8: Bubajjwe | F8: low-income | G8: 11 | H8: >60 years | I8: Male | J8: Secondary | K8: Retired | L8: 500,000 - 1,000,001 | M8: Household head | N8: > 5 years | O8: Occupied by owner | P8: Bungalow | Q8: Iron Sheets/titles | R8: Bricks | S8: Cemented | T8: Yard Tap | U8: Not Shared Facilities | V8: unpaved | W8: =(4.3+2.48)-(0.33*2) -> 6.12 | X8: =(3.7+3.46+4.3)-0.33*3 -> 10.47 | Y8: =(279-125)/1000 -> 0.154 | Z8: =1.08-0.125 -> 0.955 | AA8: =(256-125)/1000 -> 0.131 | AB8: =(741-125)/1000 -> 0.616 | AC8: =(134-125)/1000 -> 0.009 | AD8: 0 | AE8: 0 | AF8: =(1240-125)/1000 -> 1.115 | AG8: =SUM(W8:AF8) -> 19.57 | AH8: =(AG8/7) -> 2.7957143 | AI8: =AH8/G8 -> 0.25415584 | AJ8: 70 | AK8: =AG8/AJ8 -> 0.27957143
A9: 5 | B9: Household_6 | C9: Kawenpe Division | D9: Bwaise I | E9: Bubajjwe | F9: low-income | G9: 2 | H9: 18-35 years | I9: Female | J9: Tertiary | K9: Private Employee | L9: 500,000 - 1,000,000 | M9: Household head | N9: > 5 years | O9: Occupied by owner | P9: Temporary | Q9: Iron Sheets/titles | R9: Bricks | S9: Tiles | T9: House connection | U9: Not Shared Facilities | V9: unpaved | W9: 4.02 | X9: 0 | Y9: 0 | Z9: 0 | AA9: 0 | AB9: 0.05 | AC9: 0 | AD9: 0 | AE9: 0 | AF9: 0 | AG9: =SUM(W9:AF9) -> 4.07 | AH9: =(AG9/7) -> 0.58142857 | AI9: =AH9/G9 -> 0.29071429 | AJ9: 8 | AK9: =AG9/AJ9 -> 0.50875
A10: 6 | B10: Household_7 | C10: Kawenpe Division | D10: Bwaise I | E10: Bubajjwe | F10: low-income | G10: 7 | H10: 18-35 years | I10: Female | J10: Primary | K10: Retired | L10: <500,000 | M10: Household head | N10: > 5 years | O10: Occupied by owner | P10: Bungalow | Q10: Iron Sheets/titles | R10: Bricks | S10: Cemented | T10: Stand pipe | U10: Not Shared Facilities | V10: unpaved | W10: =(279-125)/1000 -> 0.154 | X10: 0 | Y10: 0 | Z10: =(301-125)/1000 -> 0.176 | AA10: =(145-125)/1000 -> 0.02 | AB10: =(154-125)/1000 -> 0.029 | AC10: =(947-330)/1000+90/1000 -> 0.707 | AD10: 0 | AE10: 0 | AF10: =(160-125)/1000 -> 0.035 | AG10: =SUM(W10:AF10) -> 1.121 | AH10: =(AG10/7) -> 0.16014286 | AI10: =AH10/G10 -> 0.022877551 | AJ10: 14 | AK10: =AG10/AJ10 -> 0.080071429
A11: 7 | B11: Household_8 | C11: Kawenpe Division | D11: Bwaise I | E11: Bubajjwe | F11: low-income | G11: 4 | H11: 36-60 years | I11: Female | J11: Secondary | K11: Business | L11: <500,000 | M11: Household head | N11: > 5 years | O11: Rented | P11: Bungalow | Q11: Iron Sheets/titles | R11: Bricks | S11: Cemented | T11: Stand pipe | U11: Shared Facilities | V11: unpaved | W11: =(3.72*10-0.33*10) -> 33.9 | X11: 0 | Y11: 0 | Z11: 0 | AA11: 0 | AB11: 0 | AC11: 0 | AD11: 0 | AE11: 0 | AF11: 0 | AG11: =SUM(W11:AF11) -> 33.9 | AH11: =(AG11/7) -> 4.8428571 | AI11: =AH11/G11 -> 1.2107143 | AJ11: 100 | AK11: =AG11/AJ11 -> 0.339
A12: 8 | B12: Household_9 | C12: Kawenpe Division | D12: Bwaise I | E12: Bubajjwe | F12: low-income | G12: 3 | H12: 18-35 years | I12: Female | J12: Primary | K12: Business | L12: <500,000 | M12: Household head | N12: 3-5 years | O12: Rented | P12: Bungalow | Q12: Iron Sheets/titles | R12: Bricks | S12: Cemented | T12: Stand pipe | U12: Shared Facilities | V12: unpaved | W12: 9.12 | X12: 0 | Y12: 0 | Z12: =(693-125)/1000 -> 0.568 | AA12: =(163-125)/1000 -> 0.038 | AB12: 0 | AC12: 0 | AD12: 0 | AE12: =(249-125)/1000 -> 0.124 | AF12: =(375+200-125)/1000 -> 0.45 | AG12: =SUM(W12:AF12) -> 10.3 | AH12: =(AG12/7) -> 1.4714286 | AI12: =AH12/G12 -> 0.49047619 | AJ12: 34 | AK12: =AG12/AJ12 -> 0.30294118
A13: 9 | B13: Household_10 | C13: Kawenpe Division | D13: Bwaise I | E13: Bubajjwe | F13: low-income | G13: 2 | H13: 36-60 years | I13: Female | J13: Primary | K13: Business | L13: <500,000 | M13: Household head | N13: 1-3 years | O13: Rented | P13: Bungalow | Q13: Iron Sheets/titles | R13: Bricks | S13: Cemented | T13: Yard Tap | U13: Shared Facilities | V13: unpaved | W13: 11.5 | X13: 0 | Y13: 0 | Z13: 0 | AA13: 0 | AB13: =(173-125)/1000 -> 0.048 | AC13: 0 | AD13: 0 | AE13: 0 | AF13: 0 | AG13: =SUM(W13:AF13) -> 11.548 | AH13: =(AG13/7) -> 1.6497143 | AI13: =AH13/G13 -> 0.82485714 | AJ13: 40 | AK13: =AG13/AJ13 -> 0.2887
A14: 10 | B14: Household_11 | C14: Kawenpe Division | D14: Bwaise I | E14: Bubajjwe | F14: low-income | G14: 3 | H14: 18-35 years | I14: Female | J14: Primary | K14: Business | L14: <500,000 | M14: Son/Daughter | N14: > 5 years | O14: Rented | P14: Bungalow | Q14: Iron Sheets/titles | R14: Bricks | S14: Cemented | T14: Stand pipe | U14: Not Shared Facilities | V14: unpaved | W14: 10.3 | X14: 0 | Y14: 0 | Z14: 0 | AA14: =(223-125)/1000 -> 0.098 | AB14: 0 | AC14: =(278-125)/1000 -> 0.153 | AD14: 0 | AE14: 0 | AF14: =(144-125)/1000 -> 0.019 | AG14: =SUM(W14:AF14) -> 10.57 | AH14: =(AG14/7) -> 1.51 | AI14: =AH14/G14 -> 0.50333333 | AJ14: 20 | AK14: =AG14/AJ14 -> 0.5285
A15: 11 | B15: Household_12 | C15: Kawenpe Division | D15: Bwaise I | E15: Bubajjwe | F15: low-income | G15: 2 | H15: 36-60 years | I15: Female | J15: Primary | K15: Business | L15: 500,000 - 1,000,000 | M15: Son/Daughter | N15: 3-5 years | O15: Rented | P15: Bungalow | Q15: Iron Sheets/titles | R15: Bricks | S15: Cemented | T15: Stand pipe | U15: Not Shared Facilities | V15: unpaved | W15: =(3.14+4.16)-0.33*2 -> 6.64 | X15: 0 | Y15: 0 | Z15: =(150-125)/1000 -> 0.025 | AA15: =(225-125)/1000 -> 0.1 | AB15: 0 | AC15: 0 | AD15: 0 | AE15: 0 | AF15: 0 | AG15: =SUM(W15:AF15) -> 6.765 | AH15: =(AG15/7) -> 0.96642857 | AI15: =AH15/G15 -> 0.48321429 | AJ15: 24 | AK15: =AG15/AJ15 -> 0.281875
A16: 12 | B16: Household_14 | C16: Kawenpe Division | D16: Bwaise I | E16: Bishop Mukwaya | F16: low-income | G16: 4 | H16: 18-35 years | I16: Male | J16: Secondary | K16: Housewife | L16: <500,000 | M16: Household head | N16: > 5 years | O16: Occupied by owner | P16: Bungalow | Q16: Iron Sheets/titles | R16: Bricks | S16: Tiles | T16: House connection | U16: Not Shared Facilities | V16: unpaved | W16: 8.52 | X16: 0 | Y16: 0 | Z16: =(180-125)/1000 -> 0.055 | AA16: 0 | AB16: 0 | AC16: 0 | AD16: 0.029 | AE16: 0 | AF16: =(454-125)/1000 -> 0.329 | AG16: =SUM(W16:AF16) -> 8.933 | AH16: =(AG16/7) -> 1.2761429 | AI16: =AH16/G16 -> 0.31903571 | AJ16: 30 | AK16: =AG16/AJ16 -> 0.29776667
A17: 13 | B17: Household_15 | C17: Kawenpe Division | D17: Bwaise I | E17: Bishop Mukwaya | F17: low-income | G17: 3 | H17: >60 years | I17: Male | J17: Primary | K17: Retired | L17: <500,000 | M17: Household head | N17: > 5 years | O17: Occupied by owner | P17: Bungalow | Q17: Iron Sheets/titles | R17: Bricks | S17: Cemented | T17: Stand pipe | U17: Not Shared Facilities | V17: unpaved | W17: =0.54-0.33 -> 0.21 | X17: 0 | Y17: 0 | Z17: 0 | AA17: 0 | AB17: =1.2-0.33 -> 0.87 | AC17: =0.9-0.33 -> 0.57 | AD17: 0 | AE17: 0 | AF17: 0.5 | AG17: =SUM(W17:AF17) -> 2.15 | AH17: =(AG17/7) -> 0.30714286 | AI17: =AH17/G17 -> 0.10238095 | AJ17: 4 | AK17: =AG17/AJ17 -> 0.5375
A18: 14 | B18: Household_16 | C18: Kawenpe Division | D18: Bwaise I | E18: Bishop Mukwaya | F18: low-income | G18: 6 | H18: 36-60 years | I18: Male | J18: Illiterate | K18: Business | L18: <500,000 | M18: Son/Daughter | N18: > 5 years | O18: Rented | P18: Bungalow | Q18: Iron Sheets/titles | R18: Bricks | S18: Cemented | T18: Stand pipe | U18: Not Shared Facilities | V18: unpaved | W18: 9.42 | X18: 0 | Y18: =(194-125)/1000 -> 0.069 | Z18: =309/1000 -> 0.309 | AA18: =(413-125)/1000 -> 0.288 | AB18: =(599-125)/1000 -> 0.474 | AC18: =(276-125)/1000 -> 0.151 | AD18: 0 | AE18: 0 | AF18: =(1.17-0.33) -> 0.84 | AG18: =SUM(W18:AF18) -> 11.551 | AH18: =(AG18/7) -> 1.6501429 | AI18: =AH18/G18 -> 0.27502381 | AJ18: 40 | AK18: =AG18/AJ18 -> 0.288775
A19: 15 | B19: Household_17 | C19: Kawenpe Division | D19: Bwaise I | E19: Bishop Mukwaya | F19: low-income | G19: 11 | H19: >60 years | I19: Male | J19: Primary | K19: Business | L19: <500,000 | M19: Household head | N19: > 5 years | O19: Occupied by owner | P19: Temporary | Q19: Iron Sheets/titles | R19: Bricks | S19: Cemented | T19: Yard Tap | U19: Not Shared Facilities | V19: unpaved | W19: 13.12 | X19: 0 | Y19: 0 | Z19: =(1.14*3-0.33*3) -> 2.43 | AA19: 0 | AB19: =1.76*3-0.33*3 -> 4.29 | AC19: =(0.782*3+0.45*3)-2*3*0.33 -> 1.716 | AD19: 0 | AE19: 0 | AF19: 0 | AG19: =SUM(W19:AF19) -> 21.556 | AH19: =(AG19/7) -> 3.0794286 | AI19: =AH19/G19 -> 0.27994805 | AJ19: 64 | AK19: =AG19/AJ19 -> 0.3368125
A20: 16 | B20: Household_18 | C20: Kawenpe Division | D20: Bwaise I | E20: Bishop Mukwaya | F20: low-income | G20: 3 | H20: 18-35 years | I20: Female | J20: Secondary | K20: Business | L20: <500,000 | M20: Household head | N20: 1-3 years | O20: Rented | P20: Bungalow | Q20: Iron Sheets/titles | R20: Mud/poles | S20: Mud | T20: Stand pipe | U20: Shared Facilities | V20: unpaved | W20: 4.18 | X20: 0 | Y20: 0 | Z20: 0 | AA20: 0 | AB20: =(632-125)/1000 -> 0.507 | AC20: 0 | AD20: 0 | AE20: 0 | AF20: =(845-330)/1000 -> 0.515 | AG20: =SUM(AB20:AF20)+4.18 -> 5.202 | AH20: =(AG20/7) -> 0.74314286 | AI20: =AH20/G20 -> 0.24771429 | AJ20: 10 | AK20: =AG20/AJ20 -> 0.5202
A21: 17 | B21: Household_19 | C21: Kawenpe Division | D21: Bwaise I | E21: Bishop Mukwaya | F21: low-income | G21: 12 | H21: 36-60 years | I21: Female | J21: Secondary | K21: Business | L21: <500,000 | M21: Household head | N21: > 5 years | O21: Occupied by owner | P21: Bungalow | Q21: Iron Sheets/titles | R21: Mud/poles | S21: Mud | T21: Stand pipe | U21: Shared Facilities | V21: unpaved | W21: =(4.26*8) -> 34.08 | X21: 0 | Y21: 0 | Z21: 0 | AA21: 0 | AB21: 0 | AC21: 0 | AD21: 0 | AE21: 0 | AF21: 0 | AG21: =W21+3.2 -> 37.28 | AH21: =(AG21/7) -> 5.3257143 | AI21: =AH21/G21 -> 0.44380952 | AJ21: 140 | AK21: =AG21/AJ21 -> 0.26628571
A22: 18 | B22: Household_21 | C22: Kawenpe Division | D22: Bwaise I | E22: Lule | F22: low-income | G22: 6 | H22: 36-60 years | I22: Male | J22: Tertiary | K22: Government Employee | L22: 1,000,000 - 3,000,000 | M22: Spouse | N22: 1-3 years | O22: Rented | P22: Bungalow | Q22: Iron Sheets/titles | R22: Bricks | S22: Tiles | T22: House connection | U22: Not Shared Facilities | V22: unpaved | W22: =4.24+6.16+5.9+6.08 -> 22.38 | X22: =(540-125)/1000 -> 0.415 | Y22: 0 | Z22: 0 | AA22: =(362-125)/1000 -> 0.237 | AB22: =(454-125)/1000 -> 0.329 | AC22: =(1171+651-330)/1000 -> 1.492 | AD22: 0 | AE22: 0 | AF22: =(411-330)/1000 -> 0.081 | AG22: =SUM(W22:AF22) -> 24.934 | AH22: =(AG22/7) -> 3.562 | AI22: =AH22/G22 -> 0.59366667 | AJ22: 70 | AK22: =AG22/AJ22 -> 0.3562
A23: 19 | B23: Household_22 | C23: Kawenpe Division | D23: Bwaise I | E23: Lule | F23: low-income | G23: 7 | H23: >60 years | I23: Male | J23: Secondary | K23: Business | L23: 500,000 - 1,000,000 | M23: Spouse | N23: > 5 years | O23: Occupied by owner | P23: Bungalow | Q23: Iron Sheets/titles | R23: Bricks | S23: Cemented | T23: Yard Tap | U23: Not Shared Facilities | V23: Unpaved | W23: 11.9 | X23: 0 | Y23: 0 | Z23: =1.355-0.33 -> 1.025 | AA23: 0 | AB23: =(1184-125)/1000 -> 1.059 | AC23: =1.032-0.33 -> 0.702 | AD23: 0 | AE23: 0 | AF23: =0.306-0.125 -> 0.181 | AG23: =SUM(W23:AF23) -> 14.867 | AH23: =(AG23/7) -> 2.1238571 | AI23: =AH23/G23 -> 0.30340816 | AJ23: 34 | AK23: =AG23/AJ23 -> 0.43726471
A24: 20 | B24: Household_23 | C24: Kawenpe Division | D24: Bwaise I | E24: Lule | F24: low-income | G24: 3 | H24: 18-35 years | I24: Male | J24: Illiterate | K24: Retired | L24: <500,000 | M24: Household head | N24: 1-3 years | O24: Rented | P24: Bungalow | Q24: Iron Sheets/titles | R24: Bricks | S24: Cemented | T24: Stand pipe | U24: Not Shared Facilities | V24: Unpaved | W24: =(2.82*7-0.125*7) -> 18.865 | X24: 0 | Y24: 0 | Z24: 0 | AA24: =(179-125)/1000 -> 0.054 | AB24: =(520-125)/1000 -> 0.395 | AC24: =(481-330)/1000 -> 0.151 | AD24: 0 | AE24: 0 | AF24: 0 | AG24: =SUM(W24:AF24) -> 19.465 | AH24: =(AG24/7) -> 2.7807143 | AI24: =AH24/G24 -> 0.92690476 | AJ24: 64 | AK24: =AG24/AJ24 -> 0.30414062
A25: 21 | B25: Household_25 | C25: Kawenpe Division | D25: Bwaise I | E25: Lule | F25: low-income | G25: 2 | H25: 18-35 years | I25: Male | J25: Secondary | K25: Private Employee | L25: 500,000 - 1,000,000 | M25: Household head | N25: 1-3 years | O25: Rented | P25: Bungalow | Q25: Iron Sheets/titles | R25: Bricks | S25: Cemented | T25: Yard Tap | U25: Not Shared Facilities | V25: Unpaved | W25: 2.9 | X25: 0 | Y25: 0 | Z25: =0.208-0.125 -> 0.083 | AA25: =0.233-0.125 -> 0.108 | AB25: =0.213-0.125 -> 0.088 | AC25: 0 | AD25: 0 | AE25: 0 | AF25: =2.68-0.125 -> 2.555 | AG25: =SUM(W25:AF25) -> 5.734 | AH25: =(AG25/7) -> 0.81914286 | AI25: =AH25/G25 -> 0.40957143 | AJ25: 34 | AK25: =AG25/AJ25 -> 0.16864706
A26: 22 | B26: Household_26 | C26: Kawenpe Division | D26: Bwaise I | E26: Lule | F26: low-income | G26: 6 | H26: 36-60 years | I26: Female | J26: Illiterate | K26: Government Employee | L26: <500,000 | M26: Household head | N26: > 5 years | O26: Occupied by owner | P26: Bungalow | Q26: Iron Sheets/titles | R26: Bricks | S26: Cemented | T26: House connection | U26: Not Shared Facilities | V26: Unpaved | W26: 12.18 | X26: 0 | Y26: 0 | Z26: =0.142-0.125 -> 0.017 | AA26: =0.159-0.125 -> 0.034 | AB26: =2-0.33 -> 1.67 | AC26: =0.277-0.125 -> 0.152 | AD26: 0 | AE26: 0.151 | AF26: 0 | AG26: =SUM(W26:AF26) -> 14.204 | AH26: =(AG26/7) -> 2.0291429 | AI26: =AH26/G26 -> 0.33819048 | AJ26: 30 | AK26: =AG26/AJ26 -> 0.47346667
A27: 23 | B27: Household_27 | C27: Kawenpe Division | D27: Bwaise I | E27: Lule | F27: low-income | G27: 3 | H27: 18-35 years | I27: Male | J27: Tertiary | K27: Private Employee | L27: 500,000 - 1,000,000 | M27: Spouse | N27: 1-3 years | O27: Rented | P27: Bungalow | Q27: Iron Sheets/titles | R27: Bricks | S27: Cemented | T27: Stand pipe | U27: Not Shared Facilities | V27: Unpaved | W27: =0.221-0.125 -> 0.096 | X27: 0 | Y27: 0 | Z27: 0 | AA27: =0.15+0.148-0.125*2 -> 0.048 | AB27: =0.177-0.125 -> 0.052 | AC27: =0.271-0.125 -> 0.146 | AD27: 0 | AE27: 0 | AF27: 0 | AG27: =SUM(W27:AF27) -> 0.342 | AH27: =(AG27/7) -> 0.048857143 | AI27: =AH27/G27 -> 0.016285714 | AJ27: 4 | AK27: =AG27/AJ27 -> 0.0855
A28: 24 | B28: Household_28 | C28: Kawenpe Division | D28: Bwaise I | E28: Lule | F28: low-income | G28: 3 | H28: 18-35 years | I28: Male | J28: Tertiary | K28: Business | L28: 500,000 - 1,000,000 | M28: Household head | N28: 1-3 years | O28: Rented | P28: Bungalow | Q28: Iron Sheets/titles | R28: Bricks | S28: Cemented | T28: Yard Tap | U28: Not Shared Facilities | V28: Unpaved | W28: =0.689-0.125 -> 0.564 | X28: 0 | Y28: 0 | Z28: 0 | AA28: 0 | AB28: =0.204-0.125 -> 0.079 | AC28: 0.142 | AD28: 0 | AE28: 0 | AF28: 0 | AG28: =SUM(W28:AF28) -> 0.785 | AH28: =(AG28/7) -> 0.11214286 | AI28: =AH28/G28 -> 0.037380952 | AJ28: 8 | AK28: =AG28/AJ28 -> 0.098125
A29: 25 | B29: Household_31 | C29: Kawenpe Division | D29: Bwaise I | E29: Lule | F29: low-income | G29: 4 | H29: 18-35 years | I29: Male | J29: Secondary | K29: Private Employee | L29: <500,000 | M29: Spouse | N29: 3-5 years | O29: Rented | P29: Bungalow | Q29: Iron Sheets/titles | R29: Bricks | S29: Cemented | T29: Yard Tap | U29: Not Shared Facilities | V29: Unpaved | W29: 7.1 | X29: 0 | Y29: 0 | Z29: =0.405-0.125 -> 0.28 | AA29: 0 | AB29: =0.585-0.125 -> 0.46 | AC29: =0.22-0.125 -> 0.095 | AD29: 0 | AE29: 0 | AF29: 0 | AG29: =SUM(W29:AF29) -> 7.935 | AH29: =(AG29/7) -> 1.1335714 | AI29: =AH29/G29 -> 0.28339286 | AJ29: 20 | AK29: =AG29/AJ29 -> 0.39675
A30: 26 | B30: Household_32 | C30: Kawenpe Division | D30: Bwaise I | E30: Lule | F30: low-income | G30: 2 | H30: 36-60 years | I30: Male | J30: Secondary | K30: Business | L30: <500,000 | M30: Spouse | N30: 1-3 years | O30: Rented | P30: Bungalow | Q30: Iron Sheets/titles | R30: Bricks | S30: Cemented | T30: Yard Tap | U30: Shared Facilities | V30: Unpaved | W30: 14.06 | X30: 0 | Y30: 0 | Z30: 0 | AA30: =0.138-0.125 -> 0.013 | AB30: =0.252-0.125 -> 0.127 | AC30: =0.214-0.125 -> 0.089 | AD30: 0 | AE30: =0.237-0.125 -> 0.112 | AF30: =0.332-0.125 -> 0.207 | AG30: =SUM(W30:AF30) -> 14.608 | AH30: =(AG30/7) -> 2.0868571 | AI30: =AH30/G30 -> 1.0434286 | AJ30: 34 | AK30: =AG30/AJ30 -> 0.42964706
A31: 27 | B31: Household_35 | C31: Kawenpe Division | D31: Bwaise I | E31: Lule | F31: low-income | G31: 5 | H31: 18-35 years | I31: Male | J31: Secondary | K31: Business | L31: <500,000 | M31: Spouse | N31: <1 year | O31: Rented | P31: Bungalow | Q31: Iron Sheets/titles | R31: Bricks | S31: Cemented | T31: Yard Tap | U31: Shared Facilities | V31: Unpaved | W31: 29.38 | X31: 9.35 | Y31: 0 | Z31: 0 | AA31: 0 | AB31: 3.28 | AC31: 1.99 | AD31: 0 | AE31: 0 | AF31: 0 | AG31: =34+10 -> 44 | AH31: =(AG31/7) -> 6.2857143 | AI31: =AH31/G31 -> 1.2571429 | AJ31: 140 | AK31: =AG31/AJ31 -> 0.31428571
A32: 28 | B32: Household_36 | C32: Kawenpe Division | D32: Bwaise I | E32: Lule | F32: low-income | G32: 3 | H32: 36-60 years | I32: Male | J32: Primary | K32: Business | L32: <500,000 | M32: Spouse | N32: 1-3 years | O32: Rented | P32: Temporary | Q32: Iron Sheets/titles | R32: Bricks | S32: Cemented | T32: Stand pipe | U32: Shared Facilities | V32: Unpaved | W32: 6.68 | X32: 0 | Y32: 0 | Z32: 0 | AA32: 0.029 | AB32: =0.505-0.125 -> 0.38 | AC32: =0.157-0.125 -> 0.032 | AD32: 0 | AE32: 0 | AF32: =0.362-0.125 -> 0.237 | AG32: =SUM(W32:AF32) -> 7.358 | AH32: =(AG32/7) -> 1.0511429 | AI32: =AH32/G32 -> 0.35038095 | AJ32: 18 | AK32: =AG32/AJ32 -> 0.40877778
A33: 29 | B33: Household_39 | C33: Kawenpe Division | D33: Bwaise I | E33: Kiyaga | F33: low-income | G33: 8 | H33: >60 years | I33: Female | J33: Primary | K33: Retired | L33: <500,000 | M33: Household head | N33: 3-5 years | O33: Occupied by owner | P33: Bungalow | Q33: Iron Sheets/titles | R33: Bricks | S33: Cemented | T33: Yard Tap | U33: Not Shared Facilities | V33: Unpaved | W33: 5.26 | X33: 0 | Y33: 0 | Z33: =0.463-0.33 -> 0.133 | AA33: =0.322-0.125 -> 0.197 | AB33: =1.591-0.33 -> 1.261 | AC33: 1.18 | AD33: 0 | AE33: 0 | AF33: 0 | AG33: =SUM(W33:AF33) -> 8.031 | AH33: =(AG33/7) -> 1.1472857 | AI33: =AH33/G33 -> 0.14341071 | AJ33: 24 | AK33: =AG33/AJ33 -> 0.334625
A34: 30 | B34: Household_41 | C34: Kawenpe Division | D34: Bwaise I | E34: Kiyaga | F34: low-income | G34: 3 | H34: 36-60 years | I34: Male | J34: Tertiary | K34: Government Employee | L34: 500,000 - 1,000,000 | M34: Household head | N34: > 5 years | O34: Occupied by owner | P34: Bungalow | Q34: Iron Sheets/titles | R34: Bricks | S34: Cemented | T34: House connection | U34: Not Shared Facilities | V34: Unpaved | W34: 1.38 | X34: 0 | Y34: 0 | Z34: 0 | AA34: =0.296-0.125 -> 0.171 | AB34: =0.342-0.125 -> 0.217 | AC34: =0.419-0.33 -> 0.089 | AD34: 0 | AE34: =0.163-0.125 -> 0.038 | AF34: 0 | AG34: =SUM(W34:AF34) -> 1.895 | AH34: =(AG34/7) -> 0.27071429 | AI34: =AH34/G34 -> 0.090238095 | AJ34: 4 | AK34: =AG34/AJ34 -> 0.47375
A35: 31 | B35: Household_44 | C35: Kawenpe Division | D35: Bwaise I | E35: Kulumba | F35: low-income | G35: 2 | H35: >60 years | I35: Female | J35: Illiterate | K35: Retired | L35: <500,000 | M35: Son/Daughter | N35: > 5 years | O35: Occupied by owner | P35: Bungalow | Q35: Iron Sheets/titles | R35: Bricks | S35: Cemented | T35: Yard Tap | U35: Shared Facilities | V35: Unpaved | W35: 8.24 | X35: 0 | Y35: 0 | Z35: 0.07 | AA35: =0.216-0.125 -> 0.091 | AB35: =0.571-0.125 -> 0.446 | AC35: =0.164-0.125 -> 0.039 | AD35: 0 | AE35: 0 | AF35: 0 | AG35: =SUM(W35:AF35) -> 8.886 | AH35: =(AG35/7) -> 1.2694286 | AI35: =AH35/G35 -> 0.63471429 | AJ35: 20 | AK35: =AG35/AJ35 -> 0.4443
A36: 32 | B36: Household_45 | C36: Kawenpe Division | D36: Bwaise I | E36: Kulumba | F36: low-income | G36: 4 | H36: 18-35 years | I36: Male | J36: Secondary | K36: Private Employee | L36: 500,000 - 1,000,000 | M36: Spouse | N36: 1-3 years | O36: Rented | P36: Bungalow | Q36: Iron Sheets/titles | R36: Bricks | S36: Cemented | T36: Stand pipe | U36: Not Shared Facilities | V36: Unpaved | W36: 4 | X36: 0 | Y36: 0 | Z36: 0 | AA36: =0.175-0.125 -> 0.05 | AB36: =0.246-0.125 -> 0.121 | AC36: 0 | AD36: 0 | AE36: 0 | AF36: 0 | AG36: =SUM(W36:AF36) -> 4.171 | AH36: =(AG36/7) -> 0.59585714 | AI36: =AH36/G36 -> 0.14896429 | AJ36: 8 | AK36: =AG36/AJ36 -> 0.521375
A37: 33 | B37: Household_46 | C37: Kawenpe Division | D37: Bwaise I | E37: Kulumba | F37: low-income | G37: 6 | H37: 36-60 years | I37: Male | J37: Secondary | K37: Business | L37: 500,000 - 1,000,000 | M37: Spouse | N37: > 5 years | O37: Rented | P37: Bungalow | Q37: Iron Sheets/titles | R37: Bricks | S37: Cemented | T37: Stand pipe | U37: Shared Facilities | V37: Unpaved | W37: 18 | X37: 0 | Y37: 0 | Z37: 0 | AA37: =0.198-0.125 -> 0.073 | AB37: =3.4-1.5-0.33 -> 1.57 | AC37: =1.166-0.5-0.33 -> 0.336 | AD37: 0 | AE37: 0 | AF37: 0 | AG37: =SUM(W37:AF37) -> 19.979 | AH37: =(AG37/7) -> 2.8541429 | AI37: =AH37/G37 -> 0.47569048 | AJ37: 74 | AK37: =AG37/AJ37 -> 0.26998649
A38: 34 | B38: Household_47 | C38: Kawenpe Division | D38: Bwaise I | E38: Kulumba | F38: low-income | G38: 4 | H38: >60 years | I38: Female | J38: Secondary | K38: Business | L38: <500,000 | M38: Household head | N38: > 5 years | O38: Occupied by owner | P38: Bungalow | Q38: Iron Sheets/titles | R38: Bricks | S38: Cemented | T38: Yard Tap | U38: Not Shared Facilities | V38: Unpaved | W38: 23.44 | X38: 0 | Y38: 0 | Z38: 0 | AA38: 0 | AB38: 2.26 | AC38: =6.68-2.26 -> 4.42 | AD38: 0 | AE38: 0 | AF38: 10.18 | AG38: =SUM(W38:AF38) -> 40.3 | AH38: =(AG38/7) -> 5.7571429 | AI38: =AH38/G38 -> 1.4392857 | AJ38: 160 | AK38: =AG38/AJ38 -> 0.251875
A39: 35 | B39: Household_48 | C39: Kawenpe Division | D39: Bwaise I | E39: Kulumba | F39: low-income | G39: 8 | H39: >60 years | I39: Female | J39: Secondary | K39: Business | L39: <500,000 | M39: Household head | N39: > 5 years | O39: Occupied by owner | P39: Bungalow | Q39: Iron Sheets/titles | R39: Bricks | S39: Cemented | T39: Yard Tap | U39: Shared Facilities | V39: Unpaved | W39: 8.7 | X39: 7.08 | Y39: 0 | Z39: =0.206-0.125 -> 0.081 | AA39: =0.156-0.125 -> 0.031 | AB39: =0.592-0.125 -> 0.467 | AC39: =0.174-0.125 -> 0.049 | AD39: 0 | AE39: 0 | AF39: 0 | AG39: =SUM(W39:AF39) -> 16.408 | AH39: =(AG39/7) -> 2.344 | AI39: =AH39/G39 -> 0.293 | AJ39: 44 | AK39: =AG39/AJ39 -> 0.37290909
A40: 36 | B40: Household_51 | C40: Kawenpe Division | D40: Bwaise I | E40: Kulumba | F40: low-income | G40: 6 | H40: >60 years | I40: Male | J40: Secondary | K40: Private Employee | L40: 500,000 - 1,000,000 | M40: Spouse | N40: > 5 years | O40: Occupied by owner | P40: Bungalow | Q40: Iron Sheets/titles | R40: Bricks | S40: Cemented | T40: House connection | U40: Not Shared Facilities | V40: Unpaved | W40: =4.64+4.2+6.44+1.24-1.42-0.33*4 -> 13.78 | X40: 10.99 | Y40: =0.355-0.125 -> 0.23 | Z40: =1.026-0.125 -> 0.901 | AA40: =0.148-0.125 -> 0.023 | AB40: =0.737-0.125 -> 0.612 | AC40: =0.205-0.125 -> 0.08 | AD40: 0 | AE40: =0.168-0.125 -> 0.043 | AF40: 0 | AG40: =SUM(W40:AF40) -> 26.659 | AH40: =(AG40/7) -> 3.8084286 | AI40: =AH40/G40 -> 0.6347381 | AJ40: 70 | AK40: =AG40/AJ40 -> 0.38084286
...

Sheet Bukoto I
A1: Solid waste Characterisation in Selected Households in Bukoto 1
A2: For Bukoto 1, the number of households that were required were 38. Bin bags were supplied to 44 households between 29th January and 5th February, though only 32 households complied and the data collected using the survey questionaires for the 32 households is shown in the table below.
A3: No. | B3: Household ID | C3: Division | D3: Parish | E3: Zone | F3: Socio-economic factors (from proposal) | K3: Other household charactristics investigated | O3: Housing facilities | W3: Amount of Solid waste collected over 7days (kg) | AG3: Total waste generated (kg) | AH3: Generation per day (kg/day) | AI3: Per Capita Generation (kg/day) | AJ3: Volume (L) | AK3: Density (kg/L)
F4: Income level | G4: Number of Occupants | H4: Age of household head | I4: Gender of Household head | J4: Education level of Household head | K4: Profession of Household head | L4: Monthly income | M4: Respondent | N4: Period of Stay in the area | O4: Type of occupancy | P4: Quality of Housing | Q4: Roof material | R4: Wall material | S4: Floor Material | T4: Access to clean Water | U4: Sanitation Facilities | V4: Condition of access road | W4: Food Waste | X4: Garden and Yard Wastes | Y4: Wood | Z4: Textiles | AA4: Paper and pulp | AB4: Polythene Bags | AC4: Plastics and Rubber | AD4: Glass | AE4: Metals | AF4: Others
A5: 1 | B5: Household_1 | C5: Nakawa | D5: Bukoto 1 | E5: Ssemwogerere | F5: Middle-Income | G5: 4 | H5: 36-60 years | I5: Male | J5: Tertiary | K5: Business | L5: 500,0000-1,000,000 | M5: Household Head | N5: > 5 years | O5: Occupied by Owner | P5: Bungalow | Q5: Iron Sheets | R5: Bricks | S5: Tiles | T5: Household Connetion | U5: Not Shared | V5: Unpaved | W5: 15 | X5: 0 | Y5: 0 | Z5: 0 | AA5: =0.19-0.125 -> 0.065 | AB5: =0.569-0.33 -> 0.239 | AC5: =0.272-0.125 -> 0.147 | AD5: 0 | AE5: 0 | AF5: =1.51-0.125 -> 1.385 | AG5: 16.84 | AH5: =AG5/7 -> 2.4057143 | AI5: =AH5/G5 -> 0.60142857 | AJ5: 70 | AK5: 0.24
A6: =A5+1 -> 2 | B6: Household_2 | C6: Nakawa | D6: Bukoto 1 | E6: Ssemwogerere | F6: Middle-Income | G6: 2 | H6: 36-60 years | I6: Male | J6: IIIiterate | K6: Private Employee | L6: less than 500,000 | M6: Household Head | N6: 1-3 years | O6: Rented | P6: Bungalow | Q6: Iron Sheets | R6: Bricks | S6: Cemented | T6: Yard Tap | U6: Shared | V6: Unpaved | W6: 5.46 | X6: =0.38-0.125 -> 0.255 | Y6: 0 | Z6: 0 | AA6: =0.159-0.125 -> 0.034 | AB6: =0.31-0.125 -> 0.185 | AC6: =0.214-0.125 -> 0.089 | AD6: 0 | AE6: 0 | AF6: =0.311-0.125 -> 0.186 | AG6: 6.21 | AH6: =AG6/7 -> 0.88714286 | AI6: =AH6/G6 -> 0.44357143 | AJ6: 8 | AK6: 0.78
A7: =A6+1 -> 3 | B7: Household_3 | C7: Nakawa | D7: Bukoto 1 | E7: Ssemwogerere | F7: Middle-Income | G7: 4 | H7: 36-60 years | I7: Female | J7: Secondray | K7: Private Employee | L7: 500,000-1,000,000 | M7: Household Head | N7: less than ayear | O7: Rented | P7: Bungalow | Q7: Iron Sheets | R7: Bricks | S7: Tiles | T7: Household Connetion | U7: Not Shared | V7: Unpaved | W7: 19.28 | X7: 0 | Y7: 0 | Z7: 0 | AA7: =0.134-0.125 -> 0.009 | AB7: =0.684-0.33 -> 0.354 | AC7: =0.322-0.125 -> 0.197 | AD7: 0 | AE7: 0 | AF7: 0.18 | AG7: 20.02 | AH7: =AG7/7 -> 2.86 | AI7: =AH7/G7 -> 0.715 | AJ7: 40 | AK7: 0.5
A8: =A7+1 -> 4 | B8: Household_4 | C8: Nakawa | D8: Bukoto 1 | E8: Ssemwogerere | F8: Middle-Income | G8: 1 | H8: 36-60 years | I8: Male | J8: Secondray | K8: Business | L8: 500,000-1,000,000 | M8: Daughter | N8: > 5 years | O8: Rented | P8: Bungalow | Q8: Iron Sheets | R8: Bricks | S8: Cemented | T8: Household Connetion | U8: Not Shared | V8: Unpaved | W8: 5.2 | X8: 0 | Y8: 0 | Z8: 0 | AA8: 0 | AB8: =0.212-0.125 -> 0.087 | AC8: =0.44-0.33 -> 0.11 | AD8: 0 | AE8: =0.22-0.125 -> 0.095 | AF8: 0 | AG8: 5.49 | AH8: =AG8/7 -> 0.78428571 | AI8: =AH8/G8 -> 0.78428571 | AJ8: 8 | AK8: 0.69
A9: =A8+1 -> 5 | B9: Household_8 | C9: Nakawa | D9: Bukoto 1 | E9: Ssemwogerere | F9: Middle-Income | G9: 3 | H9: 36-60 years | I9: Female | J9: Tertiary | K9: Private Employee | L9: 500,000-1,000,000 | M9: Spouse | N9: > 5 years | O9: Rented | P9: Bungalow | Q9: Iron Sheets | R9: Bricks | S9: Tiles | T9: Household Connetion | U9: Not Shared | V9: Unpaved | W9: 10.67 | X9: 3.68 | Y9: 0 | Z9: 0 | AA9: 1.56 | AB9: 1 | AC9: 0.32 | AD9: 0.32 | AE9: 0 | AF9: 0.96 | AG9: 18.51 | AH9: =AG9/7 -> 2.6442857 | AI9: =AH9/G9 -> 0.88142857 | AJ9: 50 | AK9: 0.37
A10: =A9+1 -> 6 | B10: Household__9 | C10: Nakawa | D10: Bukoto 1 | E10: Ssemwogerere | F10: Middle-Income | G10: 2 | H10: 18-35 years | I10: Female | J10: Secondray | K10: Business | L10: 500,000-1,000,000 | M10: Household Head | N10: < 1 year | O10: Rented | P10: Bungalow | Q10: Iron Sheets | R10: Bricks | S10: Cemented | T10: Public Standpipe | U10: Shared | V10: Unpaced | W10: 5 | X10: 2.34 | Y10: 0 | Z10: 0 | AA10: 0.05 | AB10: 0.045 | AC10: 0.243 | AD10: 0 | AE10: 0 | AF10: 0.36 | AG10: =SUM(W10:AF10) -> 8.038 | AH10: =AG10/7 -> 1.1482857 | AI10: =AH10/G10 -> 0.57414286 | AJ10: 10 | AK10: =AG10/AJ10 -> 0.8038
A11: =A10+1 -> 7 | B11: Household_10 | C11: Nakawa | D11: Bukoto 1 | E11: Ssemwogerere | F11: Middle-Income | G11: 2 | H11: 36-60 years | I11: Male | J11: Tertiary | K11: Private Employee | L11: 500,000-1,000,000 | M11: Household Head | N11: > 5 years | O11: Occupied by Owner | P11: Bungalow | Q11: Iron Sheets | R11: Bricks | S11: Cemented | T11: Yard Tap | U11: Shared | V11: Unpaved | W11: 8.17 | X11: 0 | Y11: 0 | Z11: 0 | AA11: =0.472-0.125 -> 0.347 | AB11: =0.127-0.125 -> 0.002 | AC11: 0 | AD11: 0 | AE11: 0 | AF11: =1.3 -> 1.3 | AG11: 9.82 | AH11: =AG11/7 -> 1.4028571 | AI11: =AH11/G11 -> 0.70142857 | AJ11: 12 | AK11: 0.82
A12: =A11+1 -> 8 | B12: Household_11 | C12: Nakawa | D12: Bukoto 1 | E12: Ssemwogerere | F12: Middle-Income | G12: 1 | H12: 36-60 years | I12: Male | J12: Tertiary | K12: Government Employee | L12: 500,000-1,000,000 | M12: Spouse | N12: 1-3 years | O12: Rented | P12: Bungalow | Q12: Iron Sheets | R12: Bricks | S12: Cemented | T12: Yard Tap | U12: Shared | V12: Unpaved | W12: =2.286-0.125 -> 2.161 | X12: 0 | Y12: 0 | Z12: 0 | AA12: =0.171-0.125 -> 0.046 | AB12: 0.2 | AC12: =0.141-0.125 -> 0.016 | AD12: 0 | AE12: 0 | AF12: =0.329-0.125 -> 0.204 | AG12: 2.63 | AH12: =AG12/7 -> 0.37571429 | AI12: =AH12/G12 -> 0.37571429 | AJ12: 6 | AK12: 0.44
A13: =A12+1 -> 9 | B13: Household_12 | C13: Nakawa | D13: Bukoto 1 | E13: Ssemwogerere | F13: Middle-Income | G13: 2 | H13: 36-60 years | I13: Female | J13: Tertiary | K13: Private Employee | L13: 500,000-1,000,000 | M13: Daughter | N13: > 5 years | O13: Occupied by Owner | P13: Bungalow | Q13: Iron Sheets | R13: Bricks | S13: Cemented | T13: Yard Tap | U13: Shared | V13: Unpaved | W13: =0.88+6 -> 6.88 | X13: 0 | Y13: =0.225-0.125 -> 0.1 | Z13: =0.164-0.125 -> 0.039 | AA13: =0.48-0.125 -> 0.355 | AB13: =0.562-0.125 -> 0.437 | AC13: =0.472-0.125 -> 0.347 | AD13: 0 | AE13: 0 | AF13: =0.138-0.125 -> 0.013 | AG13: 8.17 | AH13: =AG13/7 -> 1.1671429 | AI13: =AH13/G13 -> 0.58357143 | AJ13: 10 | AK13: 0.82
A14: =A13+1 -> 10 | B14: Household_13 | C14: Nakawa | D14: Bukoto 1 | E14: Ssemwogerere | F14: Middle-Income | G14: 4 | H14: 18-35 years | I14: Male | J14: Tertiary | K14: Business | L14: 500,000-1,000,000 | M14: Spouse | N14: less than ayear | O14: Rented | P14: Bungalow | Q14: Iron Sheets | R14: Bricks | S14: Tiles | T14: Household Connetion | U14: Not Shared | V14: Unpaved | W14: 18.2 | X14: 0 | Y14: 0 | Z14: =0.741-0.33 -> 0.411 | AA14: =0.293-0.125 -> 0.168 | AB14: =0.575-0.125 -> 0.45 | AC14: =0.186-0.125 -> 0.061 | AD14: 0 | AE14: 0 | AF14: 1.48 | AG14: 20.77 | AH14: =AG14/7 -> 2.9671429 | AI14: =AH14/G14 -> 0.74178571 | AJ14: 64 | AK14: 0.32
A15: =A14+1 -> 11 | B15: Househols_16 | C15: Nakawa | D15: Bukoto 1 | E15: Ssemwogerere | F15: Middle-Income | G15: 7 | H15: 36-60 years | I15: Female | J15: Tertiary | K15: Retired | L15: less than 500,000 | M15: Daughter | N15: > 5 years | O15: Occupied by Owner | P15: Bungalow | Q15: Iron Sheets | R15: Bricks | S15: Tiles | T15: Household Connetion | U15: Not Shared | V15: Unpaved | W15: 32 | X15: 1.73 | Y15: 0 | Z15: 0 | AA15: 2.14 | AB15: 0.98 | AC15: 0.052 | AD15: 0 | AE15: 0 | AF15: 1.09 | AG15: 37.99 | AH15: =AG15/7 -> 5.4271429 | AI15: =AH15/G15 -> 0.77530612 | AJ15: 120 | AK15: 0.32
A16: =A15+1 -> 12 | B16: Household_18 | C16: Nakawa | D16: Bukoto 1 | E16: Ssemwogerere | F16: Middle-Income | G16: 4 | H16: 36-60 years | I16: Female | J16: Tertiary | K16: Private Employee | L16: 500,000-1,000,000 | M16: Daughter | N16: > 5 years | O16: Rented | P16: Bungalow | Q16: Iron Sheets | R16: Bricks | S16: Cemented | T16: Yard Tap | U16: Shared | V16: Unpaved | W16: 14.62 | X16: 2.21 | Y16: 0 | Z16: 0.8 | AA16: 0.64 | AB16: 0.24 | AC16: 0.078 | AD16: 0 | AE16: 0 | AF16: 3.67 | AG16: 22.26 | AH16: =AG16/7 -> 3.18 | AI16: =AH16/G16 -> 0.795 | AJ16: 54 | AK16: 0.41
A17: =A16+1 -> 13 | B17: Household_19 | C17: Nakawa | D17: Bukoto 1 | E17: Ssemwogerere | F17: Middle-Income | G17: 9 | H17: 18-35 years | I17: Female | J17: Tertiary | K17: Government Employee | L17: 500,000-1,000,000 | M17: Niece | N17: 3-5 years | O17: Rented | P17: Bungalow | Q17: Iron Sheets | R17: Bricks | S17: Cemented | T17: Household Connetion | U17: Not Shared | V17: Unpaved | W17: =31+9.72 -> 40.72 | X17: 0 | Y17: 0 | Z17: 1.76 | AA17: =0.4-0.125 -> 0.275 | AB17: =2-0.33 -> 1.67 | AC17: =(0.546+0.758-0.125*2) -> 1.054 | AD17: 0 | AE17: 0 | AF17: 0 | AG17: 45.479 | AH17: =AG17/7 -> 6.497 | AI17: =AH17/G17 -> 0.72188889 | AJ17: 140 | AK17: 0.325
A18: =A17+1 -> 14 | B18: Household_20 | C18: Nakawa | D18: Bukoto 1 | E18: Ssemwogerere | F18: Middle-Income | G18: 6 | H18: 36-60 years | I18: Male | J18: Secondray | K18: Government Employee | L18: 500,000-1,000,000 | M18: Daughter | N18: > 5 years | O18: Occupied by Owner | P18: Bungalow | Q18: Iron Sheets | R18: Bricks | S18: Cemented | T18: Household Connetion | U18: Not Shared | V18: Unpaved | W18: =2.88*3 -> 8.64 | X18: 0 | Y18: 0 | Z18: =(1.3088-0.125)*3 -> 3.5514 | AA18: =(0.339-0.125)*3 -> 0.642 | AB18: =1.086-0.33 -> 0.756 | AC18: =(0.155-0.125)*3 -> 0.09 | AD18: 0 | AE18: =0.164-0.125 -> 0.039 | AF18: 0 | AG18: 13.7184 | AH18: =AG18/7 -> 1.9597714 | AI18: =AH18/G18 -> 0.32662857 | AJ18: 20 | AK18: 0.686
A19: =A18+1 -> 15 | B19: Household_21 | C19: Nakawa | D19: Bukoto 1 | E19: Ssemwogerere | F19: Middle-Income | G19: 2 | H19: 36-60 years | I19: Female | J19: Tertiary | K19: Government Employee | L19: 500,000-1,0000,000 | M19: Daughter | N19: 1-3 years | O19: Rented | P19: Bungalow | Q19: Iron Sheets | R19: Bricks | S19: Cemented | T19: Yard Tap | U19: Shared | V19: Unpaved | W19: 7.61 | X19: 0 | Y19: 0 | Z19: 0 | AA19: 0.005 | AB19: 0.21 | AC19: 0.194 | AD19: 0 | AE19: 0 | AF19: 0 | AG19: 8.019 | AH19: =AG19/7 -> 1.1455714 | AI19: =AH19/G19 -> 0.57278571 | AJ19: 10 | AK19: 0.802
A20: =A19+1 -> 16 | B20: Household_22 | C20: Nakawa | D20: Bukoto 1 | E20: Ssemwogerere | F20: Middle-Income | G20: 4 | H20: > 60 years | I20: Female | J20: Tertiary | K20: Retired | L20: 500,000-1,000,000 | M20: Household Head | N20: > 5 years | O20: Occupied by Owner | P20: Bungalow | Q20: Iron Sheets | R20: Bricks | S20: Tiles | T20: Household Connetion | U20: Not Shared | V20: Unpaved | W20: 20.6 | X20: 0 | Y20: 0 | Z20: 0 | AA20: 0 | AB20: =0.527-0.125 -> 0.402 | AC20: =0.265-0.125 -> 0.14 | AD20: 0 | AE20: 0 | AF20: 1.48 | AG20: 22.622 | AH20: =AG20/7 -> 3.2317143 | AI20: =AH20/G20 -> 0.80792857 | AJ20: 50 | AK20: 0.452
A21: =A20+1 -> 17 | B21: Household_23 | C21: Nakawa | D21: Bukoto 1 | E21: Ssemwogerere | F21: Middle-Income | G21: 2 | H21: 18-35 years | I21: Male | J21: Secondray | K21: Business | L21: 500,000-1,000,000 | M21: Household Head | N21: 1-3 years | O21: Rented | P21: Bungalow | Q21: Iron Sheets | R21: Bricks | S21: Tiles | T21: Yard Tap | U21: Shared | V21: Unpaved | W21: 7 | X21: 0 | Y21: 0 | Z21: 0 | AA21: 0 | AB21: 0 | AC21: =0.251+0.066-0.125 -> 0.192 | AD21: 0.193 | AE21: 0.089 | AF21: 0 | AG21: 7.474 | AH21: =AG21/7 -> 1.0677143 | AI21: =AH21/G21 -> 0.53385714 | AJ21: 10 | AK21: 0.747
A22: =A21+1 -> 18 | B22: Household_25 | C22: Nakawa | D22: Bukoto 1 | E22: Ssemwogerere | F22: Middle-Income | G22: 3 | H22: 36-60 years | I22: Male | J22: Secondray | K22: Business | L22: 500,000-1,000,000 | M22: Spouse | N22: > 5 years | O22: Occupied by Owner | P22: Bungalow | Q22: Iron Sheets | R22: Bricks | S22: Tiles | T22: Household Connetion | U22: Not Shared | V22: Unpaved | W22: =0.577-0.125+4.32+0.2 -> 4.972 | X22: 0 | Y22: 0 | Z22: 0.34 | AA22: 0 | AB22: 0.22 | AC22: =0.44-0.125 -> 0.315 | AD22: 0.218 | AE22: 0 | AF22: 0 | AG22: =SUM(W22:AF22) -> 6.065 | AH22: =AG22/7 -> 0.86642857 | AI22: =AH22/G22 -> 0.28880952 | AJ22: 12 | AK22: =AG22/AJ22 -> 0.50541667
A23: =A22+1 -> 19 | B23: Household_26 | C23: Nakawa | D23: Bukoto 1 | E23: Mukalazi | F23: Middle-Income | G23: 2 | H23: 36-60 years | I23: Male | J23: Secondray | K23: Private Employee | L23: 500,000-1,000,000 | M23: Spouse | N23: less than ayear | O23: Rented | P23: Bungalow | Q23: Iron Sheets | R23: Bricks | S23: Cemented | T23: Yard Tap | U23: Shared | V23: Unpaved | W23: 3.57 | X23: 0 | Y23: 0 | Z23: 0 | AA23: =0.202-0.125 -> 0.077 | AB23: =0.415-0.125 -> 0.29 | AC23: 0.195 | AD23: 0 | AE23: 0.177 | AF23: 2.64 | AG23: 3.379 | AH23: =AG23/7 -> 0.48271429 | AI23: =AH23/G23 -> 0.24135714 | AJ23: 6 | AK23: 0.563
A24: =A23+1 -> 20 | B24: Household_29 | C24: Nakawa | D24: Bukoto 1 | E24: Mukalazi | F24: Middle-Income | G24: 1 | H24: 18-35 years | I24: Female | J24: Tertiary | K24: Private Employee | L24: 500,000-1,000,000 | M24: Household Head | N24: > 5 years | O24: Occupied by Owner | P24: Bungalow | Q24: Iron Sheets | R24: Bricks | S24: Tiles | T24: Household Connetion | U24: Not Shared | V24: Unpaved | W24: =0.577-0.125+4.32 -> 4.772 | X24: 0 | Y24: 0 | Z24: 0 | AA24: 0 | AB24: 0.16 | AC24: =0.44-0.125 -> 0.315 | AD24: 0 | AE24: 0 | AF24: 0 | AG24: 5.247 | AH24: =AG24/7 -> 0.74957143 | AI24: =AH24/G24 -> 0.74957143 | AJ24: 8 | AK24: 0.656
A25: =A24+1 -> 21 | B25: Household_30 | C25: Nakawa | D25: Bukoto 1 | E25: Mukalazi | F25: Middle-Income | G25: 6 | H25: 18-35 years | I25: Male | J25: Secondray | K25: Private Employee | L25: 500,000-1,000,000 | M25: Household Head | N25: > 5 years | O25: Rented | P25: Bungalow | Q25: Iron Sheets | R25: Bricks | S25: Tiles | T25: Household Connetion | U25: Not Shared | V25: Unpaved | W25: 6.28 | X25: 0 | Y25: 0 | Z25: 0.137 | AA25: 0.525 | AB25: =0.583-0.125 -> 0.458 | AC25: =0.174+0.097 -> 0.271 | AD25: 0 | AE25: 0.002 | AF25: 0 | AG25: 7.67 | AH25: =AG25/7 -> 1.0957143 | AI25: =AH25/G25 -> 0.18261905 | AJ25: 10 | AK25: 0.767
A26: =A25+1 -> 22 | B26: Household_31 | C26: Nakawa | D26: Bukoto 1 | E26: Mukalazi | F26: Middle-Income | G26: 2 | H26: 18-35 years | I26: Male | J26: Tertiary | K26: Business | L26: 500,000-1,000,000 | M26: Household Head | N26: > 5 years | O26: Occupied by Owner | P26: Bungalow | Q26: Iron Sheets | R26: Bricks | S26: Cemented | T26: Yard Tap | U26: Shared | V26: Unpaved | W26: 5.22 | X26: 0 | Y26: 0 | Z26: =0.381-0.125 -> 0.256 | AA26: =0.305-0.125 -> 0.18 | AB26: =1.224-0.33 -> 0.894 | AC26: =0.182 -> 0.182 | AD26: 0 | AE26: =0.138-0.125 -> 0.013 | AF26: 1.66 | AG26: 8.41 | AH26: =AG26/7 -> 1.2014286 | AI26: =AH26/G26 -> 0.60071429 | AJ26: 10 | AK26: 0.841
A27: =A26+1 -> 23 | B27: Household_32 | C27: Nakawa | D27: Bukoto 1 | E27: Mukalazi | F27: Middle-Income | G27: 6 | H27: 18-35 years | I27: Male | J27: Primary | K27: Government Employee | L27: 500,000-1,000,000 | M27: Daughter | N27: 1-3 years | O27: Rented | P27: Bungalow | Q27: Iron Sheets | R27: Bricks | S27: Tiles | T27: Household Connetion | U27: Not Shared | V27: Unpaved | W27: 4.48 | X27: 0 | Y27: 0 | Z27: 0 | AA27: =0.614-0.33 -> 0.284 | AB27: 0.295 | AC27: 0 | AD27: 0 | AE27: 0.145 | AF27: =0.788-0.33 -> 0.458 | AG27: 5.662 | AH27: =AG27/7 -> 0.80885714 | AI27: =AH27/G27 -> 0.13480952 | AJ27: 8 | AK27: 0.708
A28: =A27+1 -> 24 | B28: Household_33 | C28: Nakawa | D28: Bukoto 1 | E28: Mukalazi | F28: Middle-Income | G28: 3 | H28: 18-35 years | I28: Female | J28: Secondray | K28: Busness | L28: 500,000-1,000-000 | M28: Household Head | N28: > 5 years | O28: Rented | P28: Bungalow | Q28: Iron Sheets | R28: Bricks | S28: Cemented | T28: Yard Tap | U28: Shared | V28: Unpaved | W28: 4.52 | X28: 0 | Y28: 0 | Z28: 0 | AA28: 0.35 | AB28: 0.364 | AC28: 0.154 | AD28: 0 | AE28: 0 | AF28: 1.03 | AG28: 6.42 | AH28: =AG28/7 -> 0.91714286 | AI28: =AH28/G28 -> 0.30571429 | AJ28: 10 | AK28: 0.642
A29: =A28+1 -> 25 | B29: Household_34 | C29: Nakawa | D29: Bukoto 1 | E29: Mukalazi | F29: Middle-Income | G29: 2 | H29: 18-35 years | I29: Male | J29: Secondray | K29: Business | L29: 500,000-1,000,000 | M29: Household Head | N29: 1-3 years | O29: Rented | P29: Bungalow | Q29: Iron Sheets | R29: Bricks | S29: Cemented | T29: Yard Tap | U29: Shared | V29: Unpaved | W29: 2 | X29: 0 | Y29: 0 | Z29: 0 | AA29: =0.439-0.125 -> 0.314 | AB29: 0.191 | AC29: 0.183 | AD29: 0 | AE29: 0 | AF29: 0 | AG29: 2.688 | AH29: =AG29/7 -> 0.384 | AI29: =AH29/G29 -> 0.192 | AJ29: 4 | AK29: 0.672
A30: =A29+1 -> 26 | B30: Household_35 | C30: Nakawa | D30: Bukoto 1 | E30: Mukalazi | F30: Middle-Income | G30: 1 | H30: 18-35 years | I30: Female | J30: Secondray | K30: Busness | L30: 500,000-1,00,000 | M30: Household Head | N30: less than ayear | O30: 0 | P30: Bungalow | Q30: Iron Sheets | R30: Bricks | S30: Cemented | T30: Yard Tap | U30: Shared | V30: Unpaved | W30: 3.89 | X30: 0 | Y30: 0 | Z30: 0 | AA30: =0.506-0.125 -> 0.381 | AB30: =0.414-0.125 -> 0.289 | AC30: =0.399-0.125 -> 0.274 | AD30: 0 | AE30: 0 | AF30: 0.53 | AG30: 4.834 | AH30: =AG30/7 -> 0.69057143 | AI30: =AH30/G30 -> 0.69057143 | AJ30: 6 | AK30: 0.806
A31: =A30+1 -> 27 | B31: Household_36 | C31: Nakawa | D31: Bukoto 1 | E31: Mukalazi | F31: Middle-Income | G31: 2 | H31: 36-60 years | I31: Male | J31: Secondray | K31: Private Employee | L31: 500,000-1,000,000 | M31: Household Head | N31: > 5 years | O31: Rented | P31: Bungalow | Q31: Iron Sheets | R31: Bricks | S31: Cemented | T31: Yard Tap | U31: Not Shared | V31: Unpaved | W31: 0.775 | X31: 0 | Y31: 0 | Z31: 0.238 | AA31: 0.332 | AB31: 0.489 | AC31: 0.333 | AD31: 0 | AE31: 0.165 | AF31: 0.189 | AG31: 2.521 | AH31: =AG31/7 -> 0.36014286 | AI31: =AH31/G31 -> 0.18007143 | AJ31: 4 | AK31: 0.63
A32: =A31+1 -> 28 | B32: Household_37 | C32: Nakawa | D32: Bukoto 1 | E32: Mukalazi | F32: Middle-Income | G32: 6 | H32: 36-60 years | I32: Male | J32: Tertiary | K32: Private Employee | L32: 500,000-1,000,000 | M32: Son | N32: > 5 years | O32: Occupied by Owner | P32: Bungalow | Q32: Iron Sheets | R32: Bricks | S32: Tiles | T32: Household Connetion | U32: Shared | V32: Unpaved | W32: 16.12 | X32: 0 | Y32: 0 | Z32: 0 | AA32: 0.319 | AB32: 0.561 | AC32: 0.599 | AD32: 0 | AE32: 0.142 | AF32: 0.757 | AG32: 18.498 | AH32: =AG32/7 -> 2.6425714 | AI32: =AH32/G32 -> 0.44042857 | AJ32: 54 | AK32: 0.343
A33: =A32+1 -> 29 | B33: Household_39 | C33: Nakawa | D33: Bukoto 1 | E33: Mukalazi | F33: Middle-Income | G33: 3 | H33: 18-35 years | I33: Male | J33: Tertiary | K33: Private Employee | L33: 500,000-1,000,000 | M33: Household Head | N33: 1-3 years | O33: Rented | P33: Bungalow | Q33: Iron Sheets | R33: Bricks | S33: Tiles | T33: Household Connetion | U33: Not Shared | V33: Unpaved | W33: 10.34 | X33: 0 | Y33: 0 | Z33: 0 | AA33: 0.384 | AB33: 0.348 | AC33: 0.388 | AD33: 0 | AE33: 0 | AF33: 1.129 | AG33: =SUM(W33:AF33) -> 12.589 | AH33: =AG33/7 -> 1.7984286 | AI33: =AH33/G33 -> 0.59947619 | AJ33: 32 | AK33: =AG33/AJ33 -> 0.39340625
A34: =A33+1 -> 30 | B34: Household_41 | C34: Nakawa | D34: Bukoto 1 | E34: Mukalazi | F34: Middle-Income | G34: 6 | H34: 18-35 years | I34: Male | J34: Tertiary | K34: Private Employee | L34: 500,000-1,000,000 | M34: Spouse | N34: 1-3 years | O34: Rented | P34: Bungalow | Q34: Iron Sheets | R34: Bricks | S34: Tiles | T34: Household Connetion | U34: Not Shared | V34: Unpaved | W34: 11.34 | X34: 0 | Y34: 0 | Z34: 0.013 | AA34: 0.294 | AB34: 0.634 | AC34: 0.627 | AD34: 0 | AE34: 0 | AF34: 0 | AG34: =SUM(W34:AF34) -> 12.908 | AH34: =AG34/7 -> 1.844 | AI34: =AH34/G34 -> 0.30733333 | AJ34: 36 | AK34: =AG34/AJ34 -> 0.35855556
A35: =A34+1 -> 31 | B35: Household_42 | C35: Nakawa | D35: Bukoto 1 | E35: Mukalazi | F35: Middle-Income | G35: 7 | H35: > 60 years | I35: Female | J35: IIIiterate | K35: Business | L35: 500,000-1,000,000 | M35: Household Head | N35: > 5 years | O35: Occupied by Owner | P35: Bungalow | Q35: Iron Sheets | R35: Bricks | S35: Cemented | T35: Public Standpipe | U35: Shared | V35: Unpaved | W35: 22.38 | X35: 0 | Y35: 0.23 | Z35: 0 | AA35: 0.691 | AB35: 0.579 | AC35: 0.345 | AD35: 0.37 | AE35: 0 | AF35: 2.78 | AG35: 27.375 | AH35: =AG35/7 -> 3.9107143 | AI35: =AH35/G35 -> 0.55867347 | AJ35: 64 | AK35: 0.428
A36: =A35+1 -> 32 | B36: Household_43 | C36: Nakawa | D36: Bukoto 1 | E36: Mukalazi | F36: Middle-Income | G36: 8 | H36: 36-60 years | I36: Male | J36: Tertiary | K36: Business | L36: 500,000-1,000,000 | M36: Son | N36: > 5 years | O36: Rented | P36: Bungalow | Q36: Iron Sheets | R36: Bricks | S36: Tiles | T36: Household Connetion | U36: Not Shared | V36: Unpaved | W36: =16.2+7.34 -> 23.54 | X36: 0 | Y36: 0 | Z36: 0 | AA36: 0.678 | AB36: 0.412 | AC36: 0.234 | AD36: 0 | AE36: 0 | AF36: 1.68 | AG36: 26.544 | AH36: =AG36/7 -> 3.792 | AI36: =AH36/G36 -> 0.474 | AJ36: 60 | AK36: 0.442
F38: Avearge Household size | G38: =AVERAGE(G5:G36) -> 3.65625 | U38: =SUM(W38:AF38) -> 428.9604 | V38: SUM | W38: =SUM(W5:W36) -> 351.41 | X38: =SUM(X5:X36) -> 10.215 | Y38: =SUM(Y5:Y36) -> 0.33 | Z38: =SUM(Z5:Z36) -> 7.5454 | AA38: =SUM(AA5:AA36) -> 11.145 | AB38: =SUM(AB5:AB36) -> 13.441 | AC38: =SUM(AC5:AC36) -> 7.745 | AD38: =SUM(AD5:AD36) -> 1.101 | ... AF38: =SUM(AF5:AF36) -> 25.161 | AI38: =AVERAGE(AI6:AI38) -> 0.53161747 | AJ38: =AVERAGE(AJ5:AJ36) -> 31.4375 | AK38: =AVERAGE(AK5:AK36) -> 0.57128683
U39: =SUM(W39:AF39) -> 1 | V39: PERCENTAGE | W39: =W38/U38 -> 0.81921315 | X39: =X38/U38 -> 0.023813387 | Y39: =Y38/U38 -> 0.00076930178 | Z39: =Z38/U38 -> 0.017589969 | AA39: =AA38/U38 -> 0.025981419 | AB39: =AB38/U38 -> 0.031333895 | AC39: =AC38/U38 -> 0.01805528 | AD39: =AD38/U38 -> 0.0025666705 | AE39: =AE38/U38 -> 0.0020211656 | AF39: =AF38/U38 -> 0.058655764
V40: AVERAGE

Sheet Ggaba
A1: Solid waste Characterisation in Selected Households in Ggaba
B2: For Ggaba, the number of households that were required were 32. Bin bags were supplied to 40 households between 19th February and 1st Match, 32 households complied and the data collected using the survey questionaires for the 32 households is shown in the table below.
A3: No. | B3: Household ID | C3: Division | D3: Parish | E3: Zone | F3: Socio-economic factors (from proposal) | K3: Other household charactristics investigated | O3: Housing facilities | W3: Amount of olid waste collected over 7days (kg) | AG3: Total waste generated(kg) | AH3: Generation per day (kg/day) | AI3: Per Capita Generation (kg/day) | AJ3: Volume(L) | AK3: Density (kg/L)
F4: Income level | G4: Number of occupants | H4: Age of Household head | I4: Gender of Household head | J4: Education level of Household head | K4: Profession of Household head | L4: Monthly income | M4: Respondent | N4: Period of Stay in the area | O4: Type of occupancy | P4: Quality of Housing | Q4: Roof material | R4: Wall material | S4: Floor Material | T4: Access to clean Water | U4: Sanitation Facilities | V4: Condition of access road | W4: Food Waste | X4: Garden and Yard wastes | Y4: Wood | Z4: Textiles | AA4: Paper and pulp | AB4: Polythene Bags | AC4: Plastics and Rubber | AD4: Glass | AE4: Metals | AF4: Others
A5: =1 -> 1 | B5: Household_1 | C5: Makindye Division | D5: Ggaba | E5: Nsubuga Godioz | F5: High-Income | G5: 6 | H5: >60 years | I5: Male | J5: Tertairy | K5: Business | L5: >3,000,000 | M5: Spouse | N5: > 5 years | O5: Occupied by owner | P5: Story Building | Q5: Tiles | R5: Bricks | S5: Tiles | T5: House Connection | U5: Not Shared Faciltiies | V5: Paved | W5: =21.2+21 -> 42.2 | X5: 0 | Y5: 0 | Z5: 0.153 | AA5: 0.586 | AB5: 0.668 | AC5: 1.03 | AD5: 0 | AE5: 0.963 | AF5: 4.38 | AG5: =SUM(W5:AF5) -> 49.98 | AH5: =AG5/7 -> 7.14 | AI5: =AH5/G5 -> 1.19 | AJ5: 160 | AK5: =AG5/AJ5 -> 0.312375
A6: =A5+1 -> 2 | B6: Household_3 | C6: Makindye Division | D6: Ggaba | E6: Nsubuga Godioz | F6: High-Income | G6: 9 | H6: 18-35 years | I6: Female | J6: Tertairy | K6: Government Employee | L6: 1,000,000-3,000,000 | M6: Household Head | N6: > 5 years | O6: Occupied by owner | P6: Story Building | Q6: Tiles | R6: Bricks | S6: Tiles | T6: House Connection | U6: Not Shared Faciltiies | V6: Paved | W6: =18.5+18.48 -> 36.98 | X6: 2.4 | Y6: 0 | Z6: 0.167 | AA6: 0.345 | AB6: 0.543 | AC6: 0.879 | AD6: 0 | AE6: 0 | AF6: 5.67 | AG6: =SUM(W6:AF6) -> 46.984 | AH6: =AG6/7 -> 6.712 | AI6: =AH6/G6 -> 0.74577778 | AJ6: 150 | AK6: =AG6/AJ6 -> 0.31322667
A7: =A6+1 -> 3 | B7: Household_4 | C7: Makindye Division | D7: Ggaba | E7: Nsubuga Godioz | F7: High-Income | G7: 8 | H7: >60 years | I7: Male | J7: Tertairy | K7: Private Employee | L7: >3,000,000 | M7: Household Head | N7: > 5 years | O7: Occupied by owner | P7: Story Building | Q7: Tiles | R7: Concrete Blocks | S7: Tiles | T7: House Connection | U7: Not Shared Faciltiies | V7: Paved | W7: 18.62 | X7: 0.534 | Y7: 0 | Z7: 0 | AA7: 0.523 | AB7: 0.782 | AC7: 0.946 | AD7: 0 | AE7: 0.834 | AF7: 0.261 | AG7: =SUM(W7:AF7) -> 22.5 | AH7: =AG7/7 -> 3.2142857 | AI7: =AH7/G7 -> 0.40178571 | AJ7: 80 | AK7: =AG7/AJ7 -> 0.28125
A8: =A7+1 -> 4 | B8: Household_5 | C8: Makindye Division | D8: Ggaba | E8: Nsubuga Godioz | F8: High-Income | G8: 2 | H8: >60 years | I8: Male | J8: Tertairy | K8: Retired | L8: 1,000,000-3,000,000 | M8: Household Head | N8: > 5 years | O8: Occupied by owner | P8: Story Building | Q8: Tiles | R8: Bricks | S8: Tiles | T8: House Connection | U8: Not Shared Faciltiies | V8: Paved | W8: 4.32 | X8: 6.12 | Y8: 0 | Z8: 0 | AA8: 0.128 | AB8: 0.45 | AC8: 0.54 | AD8: 0 | AE8: 0 | AF8: 0 | AG8: =SUM(W8:AF8) -> 11.558 | AH8: =AG8/7 -> 1.6511429 | AI8: =AH8/G8 -> 0.82557143 | AJ8: 36 | AK8: =AG8/AJ8 -> 0.32105556
A9: =A8+1 -> 5 | B9: Household_6 | C9: Makindye Division | D9: Ggaba | E9: Nsubuga Godioz | F9: High-Income | G9: 4 | H9: 36-60 years | I9: Male | J9: Tertairy | K9: Private Employee | L9: 1,000,000-3,000,000 | M9: Household Head | N9: > 5 years | O9: Occupied by owner | P9: Bungalow | Q9: Cemented | R9: Bricks | S9: Tiles | T9: House Connection | U9: Not Shared Faciltiies | V9: Paved | W9: 16.28 | X9: 0 | Y9: 0 | Z9: 0 | AA9: 0 | AB9: 0.345 | AC9: 0.563 | AD9: 0 | AE9: 0.696 | AF9: 3.216 | AG9: =SUM(W9:AF9) -> 21.1 | AH9: =AG9/7 -> 3.0142857 | AI9: =AH9/G9 -> 0.75357143 | AJ9: 68 | AK9: =AG9/AJ9 -> 0.31029412
A10: =A9+1 -> 6 | B10: Household_7 | C10: Makindye Division | D10: Ggaba | E10: Nsubuga Godioz | F10: High-Income | G10: 6 | H10: 36-60 years | I10: Male | J10: Tertairy | K10: Government Employee | L10: >3,000,000 | M10: Household Head | N10: > 5 years | O10: Occupied by owner | P10: Bungalow | Q10: Tiles | R10: Bricks | S10: Tiles | T10: House Connection | U10: Not Shared Faciltiies | V10: Paved | W10: 42 | X10: 5.784 | Y10: 0 | Z10: 0.216 | AA10: 0.835 | AB10: 2.452 | AC10: 2.675 | AD10: 0 | AE10: 2..674 | AF10: 6.12 | AG10: =SUM(W10:AF10) -> 60.082 | AH10: =AG10/7 -> 8.5831429 | AI10: =AH10/G10 -> 1.4305238 | AJ10: 200 | AK10: =AG10/AJ10 -> 0.30041
A11: =A10+1 -> 7 | B11: Household_8 | C11: Makindye Division | D11: Ggaba | E11: Nsubuga Godioz | F11: High-Income | G11: 7 | H11: 36-60 years | I11: Male | J11: Tertairy | K11: Government Employee | L11: >3,000,000 | M11: Spouse | N11: > 5 years | O11: Occupied by owner | P11: Story Building | Q11: Tiles | R11: Bricks | S11: Tiles | T11: House Connection | U11: Not Shared Faciltiies | V11: Paved | W11: 46.34 | X11: 4.284 | Y11: 0 | Z11: 0.346 | AA11: 0.785 | AB11: 1.552 | AC11: 0.806 | AD11: 0 | AE11: 0 | AF11: 0 | AG11: =SUM(W11:AF11) -> 54.113 | AH11: =AG11/7 -> 7.7304286 | AI11: =AH11/G11 -> 1.1043469 | AJ11: 186 | AK11: =AG11/AJ11 -> 0.29093011
A12: =A11+1 -> 8 | B12: Household_9 | C12: Makindye Division | D12: Ggaba | E12: Nsubuga Godioz | F12: High-Income | G12: 3 | H12: 18-35 years | I12: Male | J12: Tertairy | K12: Private Employee | L12: 1,000,000-3,000,000 | M12: Household Head | N12: > 5 years | O12: Occupied by owner | P12: Story Building | Q12: Tiles | R12: Bricks | S12: Tiles | T12: House Connection | U12: Not Shared Faciltiies | V12: Paved | W12: 8.366 | X12: 2.56 | Y12: 0 | Z12: 0.17 | AA12: 0.38 | AB12: 0.51 | AC12: 0.42 | AD12: 0 | AE12: 0 | AF12: 0 | AG12: =SUM(W12:AF12) -> 12.406 | AH12: =AG12/7 -> 1.7722857 | AI12: =AH12/G12 -> 0.5907619 | AJ12: 24 | AK12: =AG12/AJ12 -> 0.51691667
A13: =A12+1 -> 9 | B13: Household_10 | C13: Makindye Division | D13: Ggaba | E13: Nsubuga Godioz | F13: High-Income | G13: 3 | H13: >60 years | I13: Male | J13: Tertairy | K13: Private Employee | L13: >3,000,000 | M13: Household Head | N13: > 5 years | O13: Occupied by owner | P13: Story Building | Q13: Tiles | R13: Bricks | S13: Tiles | T13: House Connection | U13: Not Shared Faciltiies | V13: Unpaved | W13: 20.46 | X13: 0.565 | Y13: 0 | Z13: 0 | AA13: 0.327 | AB13: 0.509 | AC13: 0.873 | AD13: 0 | AE13: 0 | AF13: 2.03 | AG13: =SUM(W13:AF13) -> 24.764 | AH13: =AG13/7 -> 3.5377143 | AI13: =AH13/G13 -> 1.1792381 | AJ13: 74 | AK13: =AG13/AJ13 -> 0.33464865
A14: =A13+1 -> 10 | B14: Household_11 | C14: Makindye Division | D14: Ggaba | E14: Nsubuga Godioz | F14: High-Income | G14: 5 | H14: 36-60 years | I14: Male | J14: Tertairy | K14: Government Employee | L14: >3,000,000 | M14: Household Head | N14: > 5 years | O14: Rented | P14: Story Building | Q14: Tiles | R14: Bricks | S14: Tiles | T14: House Connection | U14: Not Shared Faciltiies | V14: Paved | W14: 53.52 | X14: 6.342 | Y14: 0 | Z14: 0.234 | AA14: 0.476 | AB14: 1.673 | AC14: 2.346 | AD14: 0 | AE14: 1.095 | AF14: 2.345 | AG14: =SUM(W14:AF14) -> 68.031 | AH14: =AG14/7 -> 9.7187143 | AI14: =AH14/G14 -> 1.9437429 | AJ14: 224 | AK14: =AG14/AJ14 -> 0.30370982
A15: =A14+1 -> 11 | B15: Household_12 | C15: Makindye Division | D15: Ggaba | E15: Nsubuga Godioz | F15: High-Income | G15: 4 | H15: 36-60 years | I15: Male | J15: Tertairy | K15: Government Employee | L15: >3,000,000 | M15: Household Head | N15: > 5 years | O15: Rented | P15: Story Building | Q15: Tiles | R15: Bricks | S15: Tiles | T15: House Connection | U15: Not Shared Faciltiies | V15: Paved | W15: 42.62 | X15: 3.392 | Y15: 0 | Z15: 0.434 | AA15: 0.696 | AB15: 1.873 | AC15: 1.38 | AD15: 0 | AE15: 0 | AF15: 1.348 | AG15: =SUM(W15:AF15) -> 51.743 | AH15: =AG15/7 -> 7.3918571 | AI15: =AH15/G15 -> 1.8479643 | AJ15: 174 | AK15: =AG15/AJ15 -> 0.29737356
A16: =A15+1 -> 12 | B16: Household_13 | C16: Makindye Division | D16: Ggaba | E16: Nsubuga Godioz | F16: High-Income | G16: 7 | H16: 36-60 years | I16: Male | J16: Tertairy | K16: Private Employee | L16: >3,000,000 | M16: Household Head | N16: 3-5 years | O16: Rented | P16: Story Building | Q16: Tiles | R16: Bricks | S16: Tiles | T16: House Connection | U16: Not Shared Faciltiies | V16: Paved | W16: 33.5 | X16: 0 | Y16: 0 | Z16: 0.289 | AA16: 0.128 | AB16: 0.543 | AC16: 0.326 | AD16: 0 | AE16: 0 | AF16: 6.08 | AG16: =SUM(W16:AF16) -> 40.866 | AH16: =AG16/7 -> 5.838 | AI16: =AH16/G16 -> 0.834 | AJ16: 110 | AK16: =AG16/AJ16 -> 0.37150909
